Workbook

Sheet Ave_max_min
A1: Average of Watts / CPU+GPU TDP
A2: Average of Watts / CPU+GPU TDP | B2: Column Labels
A3: Row Labels | B3: 3D U-Net-99.0 | C3: 3D U-Net-99.9 | D3: BERT-99.0 | E3: BERT-99.9 | F3: DLRM-99.0 | G3: DLRM-99.9 | H3: DLRM-v2-99 | I3: gptj-99 | J3: ResNet | K3: RetinaNet | L3: RNN-T | M3: SSD-Large | N3: Grand Total
A4: 1 | D4: 1.1382551 | E4: 1.0304796 | F4: 1.0752347 | G4: 1.0752347 | J4: 1.0523163 | L4: 1.2210714 | N4: 1.0987653
A5: 2 | B5: 0.95478333 | C5: 0.95478333 | D5: 0.97 | E5: 0.96715833 | F5: 0.96225833 | G5: 0.96225833 | J5: 0.906725 | L5: 0.94133333 | M5: 0.90225833 | N5: 0.94584687
A6: 3 | B6: 1.0097778 | C6: 1.0097778 | D6: 0.88047343 | E6: 0.88184541 | J6: 0.92771785 | L6: 0.89852174 | N6: 0.92100901
A7: 4 | B7: 0.70643445 | C7: 0.70643445 | D7: 0.87924848 | E7: 0.8712788 | F7: 0.96970956 | G7: 0.9695041 | J7: 0.82566716 | K7: 0.69336574 | L7: 0.9070227 | M7: 0.92923231 | N7: 0.8759649
A8: 5 | D8: 0.70186992 | E8: 0.65503252 | J8: 0.8421626 | M8: 0.85028049 | N8: 0.7902981
A9: 8 | B9: 0.76735481 | C9: 0.76735481 | D9: 0.85247836 | E9: 0.85233196 | F9: 0.88140755 | G9: 0.88140755 | H9: 0.70152007 | I9: 0.48412941 | J9: 0.80796144 | K9: 0.68150857 | L9: 0.83705836 | M9: 0.88023851 | N9: 0.82196232
A10: 16 | D10: 0.84516869 | E10: 0.85594242 | J10: 0.94537778 | K10: 0.59484545 | M10: 1.0373167 | N10: 0.88407879
A11: 18 | D11: 0.81261389 | E11: 0.72321667 | J11: 0.85771528 | M11: 0.90241389 | N11: 0.830735
A12: Grand Total | B12: 0.77041811 | C12: 0.77041811 | D12: 0.87301634 | E12: 0.86194986 | F12: 0.94380237 | G12: 0.94372532 | H12: 0.70152007 | I12: 0.48412941 | J12: 0.84858202 | K12: 0.67215783 | L12: 0.89637148 | M12: 0.90812512 | N12: 0.86129454
A14: Min of Watts / CPU+GPU TDP
A15: Min of Watts / CPU+GPU TDP | B15: Column Labels
A16: Row Labels | B16: 3D U-Net-99.0 | C16: 3D U-Net-99.9 | D16: BERT-99.0 | E16: BERT-99.9 | F16: DLRM-99.0 | G16: DLRM-99.9 | H16: DLRM-v2-99 | I16: gptj-99 | J16: ResNet | K16: RetinaNet | L16: RNN-T | M16: SSD-Large | N16: Grand Total
A17: 1 | D17: 1.0146531 | E17: 0.86595918 | F17: 0.89755102 | G17: 0.89755102 | J17: 0.93971429 | L17: 1.1906531 | N17: 0.86595918
A18: 2 | B18: 0.95478333 | C18: 0.95478333 | D18: 0.95983333 | E18: 0.9623 | F18: 0.95648333 | G18: 0.95648333 | J18: 0.86991667 | L18: 0.90051667 | M18: 0.86013333 | N18: 0.86013333
A19: 3 | B19: 1.0097778 | C19: 1.0097778 | D19: 0.8801256 | E19: 0.88035749 | J19: 0.8621256 | L19: 0.89518841 | N19: 0.8621256
A20: 4 | B20: 0.61384259 | C20: 0.61384259 | D20: 0.68131507 | E20: 0.68126575 | F20: 0.68766575 | G20: 0.68766575 | J20: 0.61873973 | K20: 0.68931018 | L20: 0.64675068 | M20: 0.67465753 | N20: 0.61384259
A21: 5 | D21: 0.68993496 | E21: 0.64668293 | J21: 0.78782114 | M21: 0.75873171 | N21: 0.64668293
A22: 8 | B22: 0.35450413 | C22: 0.35450413 | D22: 0.50374546 | E22: 0.51515207 | F22: 0.73339649 | G22: 0.73339649 | H22: 0.48849422 | I22: 0.36153884 | J22: 0.37489421 | K22: 0.37266116 | L22: 0.36958512 | M22: 0.73485614 | N22: 0.35450413
A23: 16 | D23: 0.66123636 | E23: 0.70494546 | J23: 0.81744242 | K23: 0.59401818 | M23: 0.90522424 | N23: 0.59401818
A24: 18 | D24: 0.79945556 | E24: 0.71912778 | J24: 0.7801 | M24: 0.87850556 | N24: 0.71912778
A25: Grand Total | B25: 0.35450413 | C25: 0.35450413 | D25: 0.50374546 | E25: 0.51515207 | F25: 0.68766575 | G25: 0.68766575 | H25: 0.48849422 | I25: 0.36153884 | J25: 0.37489421 | K25: 0.37266116 | L25: 0.36958512 | M25: 0.67465753 | N25: 0.35450413
A27: Max of Watts / CPU+GPU TDP | B27: Column Labels
A28: Row Labels | B28: 3D U-Net-99.0 | C28: 3D U-Net-99.9 | D28: BERT-99.0 | E28: BERT-99.9 | F28: DLRM-99.0 | G28: DLRM-99.9 | H28: DLRM-v2-99 | I28: gptj-99 | J28: ResNet | K28: RetinaNet | L28: RNN-T | M28: SSD-Large | N28: Grand Total
A29: 1 | D29: 1.2361633 | E29: 1.196 | F29: 1.1971429 | G29: 1.1971429 | J29: 1.147551 | L29: 1.2510204 | N29: 1.2510204
A30: 2 | B30: 0.95478333 | C30: 0.95478333 | D30: 0.98016667 | E30: 0.97201667 | F30: 0.96803333 | G30: 0.96803333 | J30: 0.94353333 | L30: 0.98215 | M30: 0.94438333 | N30: 0.98215
A31: 3 | B31: 1.0097778 | C31: 1.0097778 | D31: 0.88082126 | E31: 0.88333333 | J31: 0.99214414 | L31: 0.90185507 | N31: 1.0097778
A32: 4 | B32: 0.95983117 | C32: 0.95983117 | D32: 1.5026667 | E32: 1.4533843 | F32: 1.4514398 | G32: 1.4514398 | J32: 1.3697586 | K32: 0.6974213 | L32: 1.487 | M32: 1.4034907 | N32: 1.5026667
A33: 5 | D33: 0.71380488 | E33: 0.66338211 | J33: 0.91372358 | M33: 0.97250406 | N33: 0.97250406
A34: 8 | B34: 0.95730959 | C34: 0.95730959 | D34: 1.0162122 | E34: 1.0177184 | F34: 0.95268493 | G34: 0.95268493 | H34: 0.91982698 | I34: 0.6080746 | J34: 1.0205833 | K34: 0.93085794 | L34: 0.97895543 | M34: 1.027131 | N34: 1.027131
A35: 16 | D35: 1.0498727 | E35: 1.1400848 | J35: 1.1178667 | K35: 0.59567273 | M35: 1.1683879 | N35: 1.1683879
A36: 18 | D36: 0.82577222 | E36: 0.72730556 | J36: 0.95755556 | M36: 0.92632222 | N36: 0.95755556
A37: Grand Total | B37: 1.0097778 | C37: 1.0097778 | D37: 1.5026667 | E37: 1.4533843 | F37: 1.4514398 | G37: 1.4514398 | H37: 0.91982698 | I37: 0.6080746 | J37: 1.3697586 | K37: 0.93085794 | L37: 1.487 | M37: 1.4034907 | N37: 1.5026667
A47: Average of Watts / CPU+GPU TDP | B47: Column Labels
A48: Row Labels | B48: 1 | C48: 2 | D48: 3 | E48: 4 | F48: 5 | G48: 8 | H48: 16 | I48: 18 | J48: Grand Total
A49: NVIDIA A10 | C49: 0.94584687 | J49: 0.94584687
A50: NVIDIA A100 | D50: 0.99038739 | E50: 0.82185133 | G50: 0.87199209 | J50: 0.85323222
A51: NVIDIA A2 | B51: 1.0987653 | J51: 1.0987653
...

Sheet Sheet3
A3: Row Labels | B3: 1 | C3: 2 | D3: 3 | E3: 4 | F3: 5 | G3: 8 | H3: 16 | I3: 18
A4: 3D U-Net-99.0 | C4: 0.95478333 | D4: 1.0097778 | E4: 0.70643445 | G4: 0.76735481
A5: 3D U-Net-99.9 | C5: 0.95478333 | D5: 1.0097778 | E5: 0.70643445 | G5: 0.76735481
A6: BERT-99.0 | B6: 1.1382551 | C6: 0.97 | D6: 0.88047343 | E6: 0.87924848 | F6: 0.70186992 | G6: 0.85247836 | H6: 0.84516869 | I6: 0.81261389
A7: BERT-99.9 | B7: 1.0304796 | C7: 0.96715833 | D7: 0.88184541 | E7: 0.8712788 | F7: 0.65503252 | G7: 0.85233196 | H7: 0.85594242 | I7: 0.72321667
A8: DLRM-99.0 | B8: 1.0752347 | C8: 0.96225833 | E8: 0.96970956 | G8: 0.88140755
A9: DLRM-99.9 | B9: 1.0752347 | C9: 0.96225833 | E9: 0.9695041 | G9: 0.88140755
A10: DLRM-v2-99 | G10: 0.70152007
A11: gptj-99 | G11: 0.48412941
A12: ResNet | B12: 1.0523163 | C12: 0.906725 | D12: 0.92771785 | E12: 0.82566716 | F12: 0.8421626 | G12: 0.80796144 | H12: 0.94537778 | I12: 0.85771528
A13: RetinaNet | E13: 0.69336574 | G13: 0.68150857 | H13: 0.59484545
A14: RNN-T | B14: 1.2210714 | C14: 0.94133333 | D14: 0.89852174 | E14: 0.9070227 | G14: 0.83705836
A15: SSD-Large | C15: 0.90225833 | E15: 0.92923231 | F15: 0.85028049 | G15: 0.88023851 | H15: 1.0373167 | I15: 0.90241389
A16: Grand Total | B16: 1.0987653 | C16: 0.94584687 | D16: 0.92100901 | E16: 0.8759649 | F16: 0.7902981 | G16: 0.82196232 | H16: 0.88407879 | I16: 0.830735

Sheet Sheet2
A3: Row Labels | B3: Average of Watts / CPU+GPU TDP
A4: NVIDIA A10 | B4: 0.94584687
A5: NVIDIA A100 | B5: 0.85323222
A6: NVIDIA A2 | B6: 1.0987653
A7: NVIDIA A30 | B7: 0.90713333
A8: NVIDIA H100 | B8: 0.58286959
A9: NVIDIA T4 | B9: 1.417369
A10: QUALCOMM Cloud | B10: 0.83834494
A11: Grand Total | B11: 0.86129454

Sheet mlperf_with_tdp
A1: Source File | B1: Public ID | C1: Organization | D1: Availability | E1: System Name | F1: CPU | G1: Processors per node | H1: Total Processors | I1: GPU | J1: GPU Raw | K1: GPU Form Factor | L1: GPU Memory | M1: Accelerator Model Name | N1: Total Accelerators | O1: Division/Power | P1: # of Nodes | Q1: Accelerators per node | R1: Benchmark | S1: Benchmark Model | T1: Scenario | U1: Metric | V1: Value | W1: GPU Memory GB | X1: CPU_TDP_W | Y1: GPU_TDP_W | Z1: Total CPUs | AA1: Total GPUs | AB1: Total CPU TDP | AC1: Total GPU TDP | AD1: Total TDP | AE1: Watts / CPU+GPU TDP
A2: Table - Inference (0).csv | B2: 1.0-70 | C2: Dell EMC | D2: Available Cloud | E2: Dell EMC PowerEdge R7525 (3x A100-PCIe) | F2: AMD EPYC 7502 | G2: 2 | H2: 2 | I2: NVIDIA A100 | J2: NVIDIA A100-PCIe-40GB | K2: PCIe | L2: 40GB | M2: NVIDIA A100-PCIe-40GB | N2: 3 | O2: Closed - Power | P2: 1 | Q2: 3 | R2: Inference | S2: ResNet | T2: Offline | U2: System Watts | V2: 1101.28 | W2: 40 | X2: 180 | Y2: 250 | Z2: 2 | AA2: 3 | AB2: 360 | AC2: 750 | AD2: 1110 | AE2: 0.99214414
A3: Table - Inference (0).csv | B3: 1.0-70 | C3: Dell EMC | D3: Available Cloud | E3: Dell EMC PowerEdge R7525 (3x A100-PCIe) | F3: AMD EPYC 7502 | G3: 2 | H3: 2 | I3: NVIDIA A100 | J3: NVIDIA A100-PCIe-40GB | K3: PCIe | L3: 40GB | M3: NVIDIA A100-PCIe-40GB | N3: 3 | O3: Closed - Power | P3: 1 | Q3: 3 | R3: Inference | S3: ResNet | T3: Server | U3: System Watts | V3: 1097.38 | W3: 40 | X3: 180 | Y3: 250 | Z3: 2 | AA3: 3 | AB3: 360 | AC3: 750 | AD3: 1110 | AE3: 0.98863063
A4: Table - Inference (0).csv | B4: 1.0-71 | C4: Dell EMC | D4: Available Cloud | E4: Dell EMC PowerEdge XE2420 (4x T4) | F4: Intel(R) Xeon(R) Gold 6252 CPU @ 2.10GHz | G4: 2 | H4: 2 | I4: NVIDIA T4 | J4: NVIDIA T4 | M4: NVIDIA T4 | N4: 4 | O4: Closed - Power | P4: 1 | Q4: 4 | R4: Inference | S4: DLRM-99.0 | T4: Offline | U4: System Watts | V4: 830.13 | X4: 150 | Y4: 70 | Z4: 2 | AA4: 4 | AB4: 300 | AC4: 280 | AD4: 580 | AE4: 1.4312586
A5: Table - Inference (0).csv | B5: 1.0-71 | C5: Dell EMC | D5: Available Cloud | E5: Dell EMC PowerEdge XE2420 (4x T4) | F5: Intel(R) Xeon(R) Gold 6252 CPU @ 2.10GHz | G5: 2 | H5: 2 | I5: NVIDIA T4 | J5: NVIDIA T4 | M5: NVIDIA T4 | N5: 4 | O5: Closed - Power | P5: 1 | Q5: 4 | R5: Inference | S5: DLRM-99.0 | T5: Server | U5: System Watts | V5: 835.91 | X5: 150 | Y5: 70 | Z5: 2 | AA5: 4 | AB5: 300 | AC5: 280 | AD5: 580 | AE5: 1.4412241
A6: Table - Inference (0).csv | B6: 1.0-71 | C6: Dell EMC | D6: Available Cloud | E6: Dell EMC PowerEdge XE2420 (4x T4) | F6: Intel(R) Xeon(R) Gold 6252 CPU @ 2.10GHz | G6: 2 | H6: 2 | I6: NVIDIA T4 | J6: NVIDIA T4 | M6: NVIDIA T4 | N6: 4 | O6: Closed - Power | P6: 1 | Q6: 4 | R6: Inference | S6: DLRM-99.9 | T6: Offline | U6: System Watts | V6: 829.09 | X6: 150 | Y6: 70 | Z6: 2 | AA6: 4 | AB6: 300 | AC6: 280 | AD6: 580 | AE6: 1.4294655
A7: Table - Inference (0).csv | B7: 1.0-71 | C7: Dell EMC | D7: Available Cloud | E7: Dell EMC PowerEdge XE2420 (4x T4) | F7: Intel(R) Xeon(R) Gold 6252 CPU @ 2.10GHz | G7: 2 | H7: 2 | I7: NVIDIA T4 | J7: NVIDIA T4 | M7: NVIDIA T4 | N7: 4 | O7: Closed - Power | P7: 1 | Q7: 4 | R7: Inference | S7: DLRM-99.9 | T7: Server | U7: System Watts | V7: 835.52 | X7: 150 | Y7: 70 | Z7: 2 | AA7: 4 | AB7: 300 | AC7: 280 | AD7: 580 | AE7: 1.4405517
A8: Table - Inference (0).csv | B8: 1.0-71 | C8: Dell EMC | D8: Available Cloud | E8: Dell EMC PowerEdge XE2420 (4x T4) | F8: Intel(R) Xeon(R) Gold 6252 CPU @ 2.10GHz | G8: 2 | H8: 2 | I8: NVIDIA T4 | J8: NVIDIA T4 | M8: NVIDIA T4 | N8: 4 | O8: Closed - Power | P8: 1 | Q8: 4 | R8: Inference | S8: RNN-T | T8: Offline | U8: System Watts | V8: 856.8 | X8: 150 | Y8: 70 | Z8: 2 | AA8: 4 | AB8: 300 | AC8: 280 | AD8: 580 | AE8: 1.4772414
A9: Table - Inference (0).csv | B9: 1.0-71 | C9: Dell EMC | D9: Available Cloud | E9: Dell EMC PowerEdge XE2420 (4x T4) | F9: Intel(R) Xeon(R) Gold 6252 CPU @ 2.10GHz | G9: 2 | H9: 2 | I9: NVIDIA T4 | J9: NVIDIA T4 | M9: NVIDIA T4 | N9: 4 | O9: Closed - Power | P9: 1 | Q9: 4 | R9: Inference | S9: RNN-T | T9: Server | U9: System Watts | V9: 862.46 | X9: 150 | Y9: 70 | Z9: 2 | AA9: 4 | AB9: 300 | AC9: 280 | AD9: 580 | AE9: 1.487
A10: Table - Inference (0).csv | B10: 1.0-71 | C10: Dell EMC | D10: Available Cloud | E10: Dell EMC PowerEdge XE2420 (4x T4) | F10: Intel(R) Xeon(R) Gold 6252 CPU @ 2.10GHz | G10: 2 | H10: 2 | I10: NVIDIA T4 | J10: NVIDIA T4 | M10: NVIDIA T4 | N10: 4 | O10: Closed - Power | P10: 1 | Q10: 4 | R10: Inference | S10: ResNet | T10: Offline | U10: System Watts | V10: 794.46 | X10: 150 | Y10: 70 | Z10: 2 | AA10: 4 | AB10: 300 | AC10: 280 | AD10: 580 | AE10: 1.3697586
A11: Table - Inference (0).csv | B11: 1.0-71 | C11: Dell EMC | D11: Available Cloud | E11: Dell EMC PowerEdge XE2420 (4x T4) | F11: Intel(R) Xeon(R) Gold 6252 CPU @ 2.10GHz | G11: 2 | H11: 2 | I11: NVIDIA T4 | J11: NVIDIA T4 | M11: NVIDIA T4 | N11: 4 | O11: Closed - Power | P11: 1 | Q11: 4 | R11: Inference | S11: ResNet | T11: Server | U11: System Watts | V11: 792.69 | X11: 150 | Y11: 70 | Z11: 2 | AA11: 4 | AB11: 300 | AC11: 280 | AD11: 580 | AE11: 1.3667069
A12: Table - Inference (0).csv | B12: 1.0-71 | C12: Dell EMC | D12: Available Cloud | E12: Dell EMC PowerEdge XE2420 (4x T4) | F12: Intel(R) Xeon(R) Gold 6252 CPU @ 2.10GHz | G12: 2 | H12: 2 | I12: NVIDIA T4 | J12: NVIDIA T4 | M12: NVIDIA T4 | N12: 4 | O12: Closed - Power | P12: 1 | Q12: 4 | R12: Inference | S12: SSD-Large | T12: Offline | U12: System Watts | V12: 792.85 | X12: 150 | Y12: 70 | Z12: 2 | AA12: 4 | AB12: 300 | AC12: 280 | AD12: 580 | AE12: 1.3669828
A13: Table - Inference (0).csv | B13: 1.0-71 | C13: Dell EMC | D13: Available Cloud | E13: Dell EMC PowerEdge XE2420 (4x T4) | F13: Intel(R) Xeon(R) Gold 6252 CPU @ 2.10GHz | G13: 2 | H13: 2 | I13: NVIDIA T4 | J13: NVIDIA T4 | M13: NVIDIA T4 | N13: 4 | O13: Closed - Power | P13: 1 | Q13: 4 | R13: Inference | S13: SSD-Large | T13: Server | U13: System Watts | V13: 790.83 | X13: 150 | Y13: 70 | Z13: 2 | AA13: 4 | AB13: 300 | AC13: 280 | AD13: 580 | AE13: 1.3635
A14: Table - Inference (0).csv | B14: 1.0-72 | C14: NVIDIA | D14: Available Cloud | E14: Gigabyte G482-Z54 (8x A100-PCIe; MaxQ; TensorRT) | F14: AMD EPYC 7742 | G14: 2 | H14: 2 | I14: NVIDIA A100 | J14: NVIDIA A100-PCIe-40GB | K14: PCIe | L14: 40GB | M14: NVIDIA A100-PCIe-40GB | N14: 8 | O14: Closed - Power | P14: 1 | Q14: 8 | R14: Inference | S14: 3D U-Net-99.0 | T14: Offline | U14: System Watts | V14: 2260.88 | W14: 40 | X14: 225 | Y14: 250 | Z14: 2 | AA14: 8 | AB14: 450 | AC14: 2000 | AD14: 2450 | AE14: 0.92280816
A15: Table - Inference (0).csv | B15: 1.0-72 | C15: NVIDIA | D15: Available Cloud | E15: Gigabyte G482-Z54 (8x A100-PCIe; MaxQ; TensorRT) | F15: AMD EPYC 7742 | G15: 2 | H15: 2 | I15: NVIDIA A100 | J15: NVIDIA A100-PCIe-40GB | K15: PCIe | L15: 40GB | M15: NVIDIA A100-PCIe-40GB | N15: 8 | O15: Closed - Power | P15: 1 | Q15: 8 | R15: Inference | S15: 3D U-Net-99.9 | T15: Offline | U15: System Watts | V15: 2260.88 | W15: 40 | X15: 225 | Y15: 250 | Z15: 2 | AA15: 8 | AB15: 450 | AC15: 2000 | AD15: 2450 | AE15: 0.92280816
A16: Table - Inference (0).csv | B16: 1.0-72 | C16: NVIDIA | D16: Available Cloud | E16: Gigabyte G482-Z54 (8x A100-PCIe; MaxQ; TensorRT) | F16: AMD EPYC 7742 | G16: 2 | H16: 2 | I16: NVIDIA A100 | J16: NVIDIA A100-PCIe-40GB | K16: PCIe | L16: 40GB | M16: NVIDIA A100-PCIe-40GB | N16: 8 | O16: Closed - Power | P16: 1 | Q16: 8 | R16: Inference | S16: BERT-99.0 | T16: Offline | U16: System Watts | V16: 2289.98 | W16: 40 | X16: 225 | Y16: 250 | Z16: 2 | AA16: 8 | AB16: 450 | AC16: 2000 | AD16: 2450 | AE16: 0.93468571
A17: Table - Inference (0).csv | B17: 1.0-72 | C17: NVIDIA | D17: Available Cloud | E17: Gigabyte G482-Z54 (8x A100-PCIe; MaxQ; TensorRT) | F17: AMD EPYC 7742 | G17: 2 | H17: 2 | I17: NVIDIA A100 | J17: NVIDIA A100-PCIe-40GB | K17: PCIe | L17: 40GB | M17: NVIDIA A100-PCIe-40GB | N17: 8 | O17: Closed - Power | P17: 1 | Q17: 8 | R17: Inference | S17: BERT-99.0 | T17: Server | U17: System Watts | V17: 2308.86 | W17: 40 | X17: 225 | Y17: 250 | Z17: 2 | AA17: 8 | AB17: 450 | AC17: 2000 | AD17: 2450 | AE17: 0.94239184
A18: Table - Inference (0).csv | B18: 1.0-72 | C18: NVIDIA | D18: Available Cloud | E18: Gigabyte G482-Z54 (8x A100-PCIe; MaxQ; TensorRT) | F18: AMD EPYC 7742 | G18: 2 | H18: 2 | I18: NVIDIA A100 | J18: NVIDIA A100-PCIe-40GB | K18: PCIe | L18: 40GB | M18: NVIDIA A100-PCIe-40GB | N18: 8 | O18: Closed - Power | P18: 1 | Q18: 8 | R18: Inference | S18: BERT-99.9 | T18: Offline | U18: System Watts | V18: 2300.08 | W18: 40 | X18: 225 | Y18: 250 | Z18: 2 | AA18: 8 | AB18: 450 | AC18: 2000 | AD18: 2450 | AE18: 0.93880816
A19: Table - Inference (0).csv | B19: 1.0-72 | C19: NVIDIA | D19: Available Cloud | E19: Gigabyte G482-Z54 (8x A100-PCIe; MaxQ; TensorRT) | F19: AMD EPYC 7742 | G19: 2 | H19: 2 | I19: NVIDIA A100 | J19: NVIDIA A100-PCIe-40GB | K19: PCIe | L19: 40GB | M19: NVIDIA A100-PCIe-40GB | N19: 8 | O19: Closed - Power | P19: 1 | Q19: 8 | R19: Inference | S19: BERT-99.9 | T19: Server | U19: System Watts | V19: 2263.46 | W19: 40 | X19: 225 | Y19: 250 | Z19: 2 | AA19: 8 | AB19: 450 | AC19: 2000 | AD19: 2450 | AE19: 0.92386122
A20: Table - Inference (0).csv | B20: 1.0-72 | C20: NVIDIA | D20: Available Cloud | E20: Gigabyte G482-Z54 (8x A100-PCIe; MaxQ; TensorRT) | F20: AMD EPYC 7742 | G20: 2 | H20: 2 | I20: NVIDIA A100 | J20: NVIDIA A100-PCIe-40GB | K20: PCIe | L20: 40GB | M20: NVIDIA A100-PCIe-40GB | N20: 8 | O20: Closed - Power | P20: 1 | Q20: 8 | R20: Inference | S20: RNN-T | T20: Offline | U20: System Watts | V20: 2278.42 | W20: 40 | X20: 225 | Y20: 250 | Z20: 2 | AA20: 8 | AB20: 450 | AC20: 2000 | AD20: 2450 | AE20: 0.92996735
A21: Table - Inference (0).csv | B21: 1.0-72 | C21: NVIDIA | D21: Available Cloud | E21: Gigabyte G482-Z54 (8x A100-PCIe; MaxQ; TensorRT) | F21: AMD EPYC 7742 | G21: 2 | H21: 2 | I21: NVIDIA A100 | J21: NVIDIA A100-PCIe-40GB | K21: PCIe | L21: 40GB | M21: NVIDIA A100-PCIe-40GB | N21: 8 | O21: Closed - Power | P21: 1 | Q21: 8 | R21: Inference | S21: RNN-T | T21: Server | U21: System Watts | V21: 2324.84 | W21: 40 | X21: 225 | Y21: 250 | Z21: 2 | AA21: 8 | AB21: 450 | AC21: 2000 | AD21: 2450 | AE21: 0.94891429
A22: Table - Inference (0).csv | B22: 1.0-72 | C22: NVIDIA | D22: Available Cloud | E22: Gigabyte G482-Z54 (8x A100-PCIe; MaxQ; TensorRT) | F22: AMD EPYC 7742 | G22: 2 | H22: 2 | I22: NVIDIA A100 | J22: NVIDIA A100-PCIe-40GB | K22: PCIe | L22: 40GB | M22: NVIDIA A100-PCIe-40GB | N22: 8 | O22: Closed - Power | P22: 1 | Q22: 8 | R22: Inference | S22: ResNet | T22: Offline | U22: System Watts | V22: 2195.06 | W22: 40 | X22: 225 | Y22: 250 | Z22: 2 | AA22: 8 | AB22: 450 | AC22: 2000 | AD22: 2450 | AE22: 0.89594286
A23: Table - Inference (0).csv | B23: 1.0-72 | C23: NVIDIA | D23: Available Cloud | E23: Gigabyte G482-Z54 (8x A100-PCIe; MaxQ; TensorRT) | F23: AMD EPYC 7742 | G23: 2 | H23: 2 | I23: NVIDIA A100 | J23: NVIDIA A100-PCIe-40GB | K23: PCIe | L23: 40GB | M23: NVIDIA A100-PCIe-40GB | N23: 8 | O23: Closed - Power | P23: 1 | Q23: 8 | R23: Inference | S23: ResNet | T23: Server | U23: System Watts | V23: 2245.33 | W23: 40 | X23: 225 | Y23: 250 | Z23: 2 | AA23: 8 | AB23: 450 | AC23: 2000 | AD23: 2450 | AE23: 0.91646122
A24: Table - Inference (0).csv | B24: 1.0-72 | C24: NVIDIA | D24: Available Cloud | E24: Gigabyte G482-Z54 (8x A100-PCIe; MaxQ; TensorRT) | F24: AMD EPYC 7742 | G24: 2 | H24: 2 | I24: NVIDIA A100 | J24: NVIDIA A100-PCIe-40GB | K24: PCIe | L24: 40GB | M24: NVIDIA A100-PCIe-40GB | N24: 8 | O24: Closed - Power | P24: 1 | Q24: 8 | R24: Inference | S24: SSD-Large | T24: Offline | U24: System Watts | V24: 2244.06 | W24: 40 | X24: 225 | Y24: 250 | Z24: 2 | AA24: 8 | AB24: 450 | AC24: 2000 | AD24: 2450 | AE24: 0.91594286
A25: Table - Inference (0).csv | B25: 1.0-72 | C25: NVIDIA | D25: Available Cloud | E25: Gigabyte G482-Z54 (8x A100-PCIe; MaxQ; TensorRT) | F25: AMD EPYC 7742 | G25: 2 | H25: 2 | I25: NVIDIA A100 | J25: NVIDIA A100-PCIe-40GB | K25: PCIe | L25: 40GB | M25: NVIDIA A100-PCIe-40GB | N25: 8 | O25: Closed - Power | P25: 1 | Q25: 8 | R25: Inference | S25: SSD-Large | T25: Server | U25: System Watts | V25: 2259.64 | W25: 40 | X25: 225 | Y25: 250 | Z25: 2 | AA25: 8 | AB25: 450 | AC25: 2000 | AD25: 2450 | AE25: 0.92230204
... A57: Table - Inference (0).csv | B57: 1.0-74 | C57: NVIDIA | D57: Available Cloud | E57: NVIDIA DGX Station A100 (4x A100-SXM-80GB; MaxQ; TensorRT) | F57: AMD EPYC 7742 | G57: 1 | H57: 1 | I57: NVIDIA A100 | J57: NVIDIA A100-SXM-80GB | K57: SXM | L57: 80GB | M57: NVIDIA A100-SXM-80GB | N57: 4 | O57: Closed - Power | P57: 1 | Q57: 4 | R57: Inference | S57: SSD-Large | T57: Server | U57: System Watts | V57: 1266.86 | W57: 80 | X57: 225 | Y57: 400 | Z57: 1 | AA57: 4 | AB57: 225 | AC57: 1600 | AD57: 1825 | AE57: 0.69416986
A58: Table - Inference (0).csv | B58: 1.0-75 | C58: Qualcomm | D58: Available Cloud | E58: Gigabyte R282-Z93 5x QAIC100 | F58: AMD EPYC 7282 16-Core Processor | G58: 2 | H58: 2 | I58: QUALCOMM Cloud | J58: QUALCOMM Cloud AI 100 PCIe HHHL | K58: PCIe | M58: QUALCOMM Cloud AI 100 PCIe HHHL | N58: 5 | O58: Closed - Power | P58: 1 | Q58: 5 | R58: Inference | S58: ResNet | T58: Offline | U58: System Watts | V58: 561.94 | X58: 120 | Y58: 75 | Z58: 2 | AA58: 5 | AB58: 240 | AC58: 375 | AD58: 615 | AE58: 0.91372358
A59: Table - Inference (0).csv | B59: 1.0-75 | C59: Qualcomm | D59: Available Cloud | E59: Gigabyte R282-Z93 5x QAIC100 | F59: AMD EPYC 7282 16-Core Processor | G59: 2 | H59: 2 | I59: QUALCOMM Cloud | J59: QUALCOMM Cloud AI 100 PCIe HHHL | K59: PCIe | M59: QUALCOMM Cloud AI 100 PCIe HHHL | N59: 5 | O59: Closed - Power | P59: 1 | Q59: 5 | R59: Inference | S59: ResNet | T59: Server | U59: System Watts | V59: 533.81 | X59: 120 | Y59: 75 | Z59: 2 | AA59: 5 | AB59: 240 | AC59: 375 | AD59: 615 | AE59: 0.86798374
A60: Table - Inference (0).csv | B60: 1.0-75 | C60: Qualcomm | D60: Available Cloud | E60: Gigabyte R282-Z93 5x QAIC100 | F60: AMD EPYC 7282 16-Core Processor | G60: 2 | H60: 2 | I60: QUALCOMM Cloud | J60: QUALCOMM Cloud AI 100 PCIe HHHL | K60: PCIe | M60: QUALCOMM Cloud AI 100 PCIe HHHL | N60: 5 | O60: Closed - Power | P60: 1 | Q60: 5 | R60: Inference | S60: SSD-Large | T60: Offline | U60: System Watts | V60: 598.09 | X60: 120 | Y60: 75 | Z60: 2 | AA60: 5 | AB60: 240 | AC60: 375 | AD60: 615 | AE60: 0.97250406
A61: Table - Inference (0).csv | B61: 1.0-75 | C61: Qualcomm | D61: Available Cloud | E61: Gigabyte R282-Z93 5x QAIC100 | F61: AMD EPYC 7282 16-Core Processor | G61: 2 | H61: 2 | I61: QUALCOMM Cloud | J61: QUALCOMM Cloud AI 100 PCIe HHHL | K61: PCIe | M61: QUALCOMM Cloud AI 100 PCIe HHHL | N61: 5 | O61: Closed - Power | P61: 1 | Q61: 5 | R61: Inference | S61: SSD-Large | T61: Server | U61: System Watts | V61: 547.83 | X61: 120 | Y61: 75 | Z61: 2 | AA61: 5 | AB61: 240 | AC61: 375 | AD61: 615 | AE61: 0.89078049
A62: Table - Inference (1).csv | B62: 1.1-006 | C62: Dell | D62: Available Cloud | E62: Dell EMC PowerEdge R750xa (4x A100-PCIE-40GB; MaxQ; TensorRT) | F62: Intel(R) Xeon(R) Platinum 8368 CPU @ 2.40GHz | G62: 2 | H62: 2 | I62: NVIDIA A100 | J62: NVIDIA A100-PCIE-40GB | K62: PCIe | L62: 40GB | M62: NVIDIA A100-PCIE-40GB | N62: 4 | O62: Closed - Power | P62: 1 | Q62: 4 | R62: Inference | S62: 3D U-Net-99.0 | T62: Offline | U62: System Watts | V62: 1478.14 | W62: 40 | X62: 270 | Y62: 250 | Z62: 2 | AA62: 4 | AB62: 540 | AC62: 1000 | AD62: 1540 | AE62: 0.95983117
A63: Table - Inference (1).csv | B63: 1.1-006 | C63: Dell | D63: Available Cloud | E63: Dell EMC PowerEdge R750xa (4x A100-PCIE-40GB; MaxQ; TensorRT) | F63: Intel(R) Xeon(R) Platinum 8368 CPU @ 2.40GHz | G63: 2 | H63: 2 | I63: NVIDIA A100 | J63: NVIDIA A100-PCIE-40GB | K63: PCIe | L63: 40GB | M63: NVIDIA A100-PCIE-40GB | N63: 4 | O63: Closed - Power | P63: 1 | Q63: 4 | R63: Inference | S63: 3D U-Net-99.9 | T63: Offline | U63: System Watts | V63: 1478.14 | W63: 40 | X63: 270 | Y63: 250 | Z63: 2 | AA63: 4 | AB63: 540 | AC63: 1000 | AD63: 1540 | AE63: 0.95983117
A64: Table - Inference (1).csv | B64: 1.1-006 | C64: Dell | D64: Available Cloud | E64: Dell EMC PowerEdge R750xa (4x A100-PCIE-40GB; MaxQ; TensorRT) | F64: Intel(R) Xeon(R) Platinum 8368 CPU @ 2.40GHz | G64: 2 | H64: 2 | I64: NVIDIA A100 | J64: NVIDIA A100-PCIE-40GB | K64: PCIe | L64: 40GB | M64: NVIDIA A100-PCIE-40GB | N64: 4 | O64: Closed - Power | P64: 1 | Q64: 4 | R64: Inference | S64: BERT-99.0 | T64: Offline | U64: System Watts | V64: 1474.35 | W64: 40 | X64: 270 | Y64: 250 | Z64: 2 | AA64: 4 | AB64: 540 | AC64: 1000 | AD64: 1540 | AE64: 0.95737013
A65: Table - Inference (1).csv | B65: 1.1-006 | C65: Dell | D65: Available Cloud | E65: Dell EMC PowerEdge R750xa (4x A100-PCIE-40GB; MaxQ; TensorRT) | F65: Intel(R) Xeon(R) Platinum 8368 CPU @ 2.40GHz | G65: 2 | H65: 2 | I65: NVIDIA A100 | J65: NVIDIA A100-PCIE-40GB | K65: PCIe | L65: 40GB | M65: NVIDIA A100-PCIE-40GB | N65: 4 | O65: Closed - Power | P65: 1 | Q65: 4 | R65: Inference | S65: BERT-99.0 | T65: Server | U65: System Watts | V65: 1480.35 | W65: 40 | X65: 270 | Y65: 250 | Z65: 2 | AA65: 4 | AB65: 540 | AC65: 1000 | AD65: 1540 | AE65: 0.96126623
A66: Table - Inference (1).csv | B66: 1.1-006 | C66: Dell | D66: Available Cloud | E66: Dell EMC PowerEdge R750xa (4x A100-PCIE-40GB; MaxQ; TensorRT) | F66: Intel(R) Xeon(R) Platinum 8368 CPU @ 2.40GHz | G66: 2 | H66: 2 | I66: NVIDIA A100 | J66: NVIDIA A100-PCIE-40GB | K66: PCIe | L66: 40GB | M66: NVIDIA A100-PCIE-40GB | N66: 4 | O66: Closed - Power | P66: 1 | Q66: 4 | R66: Inference | S66: BERT-99.9 | T66: Offline | U66: System Watts | V66: 1475.89 | W66: 40 | X66: 270 | Y66: 250 | Z66: 2 | AA66: 4 | AB66: 540 | AC66: 1000 | AD66: 1540 | AE66: 0.95837013
A67: Table - Inference (1).csv | B67: 1.1-006 | C67: Dell | D67: Available Cloud | E67: Dell EMC PowerEdge R750xa (4x A100-PCIE-40GB; MaxQ; TensorRT) | F67: Intel(R) Xeon(R) Platinum 8368 CPU @ 2.40GHz | G67: 2 | H67: 2 | I67: NVIDIA A100 | J67: NVIDIA A100-PCIE-40GB | K67: PCIe | L67: 40GB | M67: NVIDIA A100-PCIE-40GB | N67: 4 | O67: Closed - Power | P67: 1 | Q67: 4 | R67: Inference | S67: BERT-99.9 | T67: Server | U67: System Watts | V67: 1468.54 | W67: 40 | X67: 270 | Y67: 250 | Z67: 2 | AA67: 4 | AB67: 540 | AC67: 1000 | AD67: 1540 | AE67: 0.9535974
A68: Table - Inference (1).csv | B68: 1.1-006 | C68: Dell | D68: Available Cloud | E68: Dell EMC PowerEdge R750xa (4x A100-PCIE-40GB; MaxQ; TensorRT) | F68: Intel(R) Xeon(R) Platinum 8368 CPU @ 2.40GHz | G68: 2 | H68: 2 | I68: NVIDIA A100 | J68: NVIDIA A100-PCIE-40GB | K68: PCIe | L68: 40GB | M68: NVIDIA A100-PCIE-40GB | N68: 4 | O68: Closed - Power | P68: 1 | Q68: 4 | R68: Inference | S68: ResNet | T68: Offline | U68: System Watts | V68: 1431.04 | W68: 40 | X68: 270 | Y68: 250 | Z68: 2 | AA68: 4 | AB68: 540 | AC68: 1000 | AD68: 1540 | AE68: 0.92924675
A69: Table - Inference (1).csv | B69: 1.1-006 | C69: Dell | D69: Available Cloud | E69: Dell EMC PowerEdge R750xa (4x A100-PCIE-40GB; MaxQ; TensorRT) | F69: Intel(R) Xeon(R) Platinum 8368 CPU @ 2.40GHz | G69: 2 | H69: 2 | I69: NVIDIA A100 | J69: NVIDIA A100-PCIE-40GB | K69: PCIe | L69: 40GB | M69: NVIDIA A100-PCIE-40GB | N69: 4 | O69: Closed - Power | P69: 1 | Q69: 4 | R69: Inference | S69: ResNet | T69: Server | U69: System Watts | V69: 1446.16 | W69: 40 | X69: 270 | Y69: 250 | Z69: 2 | AA69: 4 | AB69: 540 | AC69: 1000 | AD69: 1540 | AE69: 0.93906493
A70: Table - Inference (1).csv | B70: 1.1-006 | C70: Dell | D70: Available Cloud | E70: Dell EMC PowerEdge R750xa (4x A100-PCIE-40GB; MaxQ; TensorRT) | F70: Intel(R) Xeon(R) Platinum 8368 CPU @ 2.40GHz | G70: 2 | H70: 2 | I70: NVIDIA A100 | J70: NVIDIA A100-PCIE-40GB | K70: PCIe | L70: 40GB | M70: NVIDIA A100-PCIE-40GB | N70: 4 | O70: Closed - Power | P70: 1 | Q70: 4 | R70: Inference | S70: SSD-Large | T70: Offline | U70: System Watts | V70: 1448.13 | W70: 40 | X70: 270 | Y70: 250 | Z70: 2 | AA70: 4 | AB70: 540 | AC70: 1000 | AD70: 1540 | AE70: 0.94034416
A71: Table - Inference (1).csv | B71: 1.1-006 | C71: Dell | D71: Available Cloud | E71: Dell EMC PowerEdge R750xa (4x A100-PCIE-40GB; MaxQ; TensorRT) | F71: Intel(R) Xeon(R) Platinum 8368 CPU @ 2.40GHz | G71: 2 | H71: 2 | I71: NVIDIA A100 | J71: NVIDIA A100-PCIE-40GB | K71: PCIe | L71: 40GB | M71: NVIDIA A100-PCIE-40GB | N71: 4 | O71: Closed - Power | P71: 1 | Q71: 4 | R71: Inference | S71: SSD-Large | T71: Server | U71: System Watts | V71: 1436.47 | W71: 40 | X71: 270 | Y71: 250 | Z71: 2 | AA71: 4 | AB71: 540 | AC71: 1000 | AD71: 1540 | AE71: 0.93277273
...

Sheet Sheet1
F2: =SUM(F4:F20) -> 442 | J2: P10 | K2: =PERCENTILE(mlperf_with_tdp!$AE$2:$AE$443,0.1) -> 0.65248772
J3: P50 | K3: =PERCENTILE(mlperf_with_tdp!$AE$2:$AE$443,0.5) -> 0.86797738
E4: 0.1 | F4: =COUNTIFS(mlperf_with_tdp!$AE$2:$AE$443,">="&E4,mlperf_with_tdp!$AE$2:$AE$443,"<"&E5) -> 0 | G4: =F4/$F$2 -> 0 | J4: P90 | K4: =PERCENTILE(mlperf_with_tdp!$AE$2:$AE$443,0.9) -> 1.0831429
E5: =E4+0.1 -> 0.2 | F5: =COUNTIFS(mlperf_with_tdp!$AE$2:$AE$443,">="&E5,mlperf_with_tdp!$AE$2:$AE$443,"<"&E6) -> 0 | G5: =F5/$F$2 -> 0 | J5: P95 | K5: =PERCENTILE(mlperf_with_tdp!$AE$2:$AE$443,0.95) -> 1.2356989
E6: =E5+0.1 -> 0.3 | F6: =COUNTIFS(mlperf_with_tdp!$AE$2:$AE$443,">="&E6,mlperf_with_tdp!$AE$2:$AE$443,"<"&E7) -> 10 | G6: =F6/$F$2 -> 0.022624434
E7: =E6+0.1 -> 0.4 | F7: =COUNTIFS(mlperf_with_tdp!$AE$2:$AE$443,">="&E7,mlperf_with_tdp!$AE$2:$AE$443,"<"&E8) -> 1 | G7: =F7/$F$2 -> 0.0022624434
E8: =E7+0.1 -> 0.5 | F8: =COUNTIFS(mlperf_with_tdp!$AE$2:$AE$443,">="&E8,mlperf_with_tdp!$AE$2:$AE$443,"<"&E9) -> 9 | G8: =F8/$F$2 -> 0.020361991
E9: =E8+0.1 -> 0.6 | F9: =COUNTIFS(mlperf_with_tdp!$AE$2:$AE$443,">="&E9,mlperf_with_tdp!$AE$2:$AE$443,"<"&E10) -> 68 | G9: =F9/$F$2 -> 0.15384615
E10: =E9+0.1 -> 0.7 | F10: =COUNTIFS(mlperf_with_tdp!$AE$2:$AE$443,">="&E10,mlperf_with_tdp!$AE$2:$AE$443,"<"&E11) -> 75 | G10: =F10/$F$2 -> 0.16968326
E11: =E10+0.1 -> 0.8 | F11: =COUNTIFS(mlperf_with_tdp!$AE$2:$AE$443,">="&E11,mlperf_with_tdp!$AE$2:$AE$443,"<"&E12) -> 91 | G11: =F11/$F$2 -> 0.20588235
E12: =E11+0.1 -> 0.9 | F12: =COUNTIFS(mlperf_with_tdp!$AE$2:$AE$443,">="&E12,mlperf_with_tdp!$AE$2:$AE$443,"<"&E13) -> 130 | G12: =F12/$F$2 -> 0.29411765
E13: =E12+0.1 -> 1 | F13: =COUNTIFS(mlperf_with_tdp!$AE$2:$AE$443,">="&E13,mlperf_with_tdp!$AE$2:$AE$443,"<"&E14) -> 16 | G13: =F13/$F$2 -> 0.036199095
E14: =E13+0.1 -> 1.1 | F14: =COUNTIFS(mlperf_with_tdp!$AE$2:$AE$443,">="&E14,mlperf_with_tdp!$AE$2:$AE$443,"<"&E15) -> 17 | G14: =F14/$F$2 -> 0.038461538
E15: =E14+0.1 -> 1.2 | F15: =COUNTIFS(mlperf_with_tdp!$AE$2:$AE$443,">="&E15,mlperf_with_tdp!$AE$2:$AE$443,"<"&E16) -> 7 | G15: =F15/$F$2 -> 0.015837104
E16: =E15+0.1 -> 1.3 | F16: =COUNTIFS(mlperf_with_tdp!$AE$2:$AE$443,">="&E16,mlperf_with_tdp!$AE$2:$AE$443,"<"&E17) -> 5 | G16: =F16/$F$2 -> 0.011312217
E17: =E16+0.1 -> 1.4 | F17: =COUNTIFS(mlperf_with_tdp!$AE$2:$AE$443,">="&E17,mlperf_with_tdp!$AE$2:$AE$443,"<"&E18) -> 12 | G17: =F17/$F$2 -> 0.027149321
... E19: =E18+0.1 -> 1.6 | F19: =COUNTIFS(mlperf_with_tdp!$AE$2:$AE$443,">="&E19,mlperf_with_tdp!$AE$2:$AE$443,"<"&E20) -> 0 | G19: =F19/$F$2 -> 0
E20: 1.7 | F20: =COUNTIFS(mlperf_with_tdp!$AE$2:$AE$443,">="&E20,mlperf_with_tdp!$AE$2:$AE$443,"<"&E21) -> 0 | G20: =F20/$F$2 -> 0
